<?xml version="1.0" encoding="utf-8"?><testsuite errors="0" failures="1" name="pytest" skips="0" tests="1" time="12.366"><testcase classname="scripts.FileUpload.CheckFileUpload" name="test_local_upload" time="8.56543397903"><failure message="test failure">Traceback (most recent call last):
  File &quot;/Users/adam/work/saunter/py.saunter-examples/picpaste/webdriver/conftest.py&quot;, line 32, in pytest_runtest_call
    raise(e)
AttributeError: &apos;ConfigWrapper&apos; object has no attribute &apos;get&apos;</failure></testcase></testsuite>