<?xml version="1.0" encoding="utf-8"?><testsuite errors="0" failures="1" name="" skips="0" tests="1" time="28.312"><testcase classname="scripts.FileUpload.CheckFileUpload" name="test_local_upload" time="17.3964629173"><failure message="test failure">Traceback (most recent call last):
  File &quot;/Users/adam/work/saunter/py.saunter-examples/picpaste/webdriver/conftest.py&quot;, line 32, in pytest_runtest_call
    raise(e)
TimeoutException: Message: &apos;&apos;</failure><system-out>[[ATTACHMENT|/Users/adam/work/saunter/py.saunter-examples/picpaste/webdriver/logs/2013-04-15-18-28-49/CheckFileUpload/test_local_upload/exception.png]]</system-out></testcase></testsuite>