<?xml version="1.0" encoding="utf-8"?><testsuite errors="1" failures="0" name="" skips="0" tests="0" time="24.976"><testcase classname="pytest" name="internal"><error message="internal error">Traceback (most recent call last):
  File &amp;quot;/Library/Frameworks/Python.framework/Versions/2.7/lib/python2.7/site-packages/_pytest/main.py&amp;quot;, line 81, in wrap_session
    doit(config, session)
  File &amp;quot;/Library/Frameworks/Python.framework/Versions/2.7/lib/python2.7/site-packages/_pytest/main.py&amp;quot;, line 113, in _main
    config.hook.pytest_runtestloop(session=session)
  File &amp;quot;/Library/Frameworks/Python.framework/Versions/2.7/lib/python2.7/site-packages/_pytest/core.py&amp;quot;, line 422, in __call__
    return self._docall(methods, kwargs)
  File &amp;quot;/Library/Frameworks/Python.framework/Versions/2.7/lib/python2.7/site-packages/_pytest/core.py&amp;quot;, line 433, in _docall
    res = mc.execute()
  File &amp;quot;/Library/Frameworks/Python.framework/Versions/2.7/lib/python2.7/site-packages/_pytest/core.py&amp;quot;, line 351, in execute
    res = method(**kwargs)
  File &amp;quot;/Library/Frameworks/Python.framework/Versions/2.7/lib/python2.7/site-packages/_pytest/main.py&amp;quot;, line 133, in pytest_runtestloop
    item.config.hook.pytest_runtest_protocol(item=item, nextitem=nextitem)
  File &amp;quot;/Library/Frameworks/Python.framework/Versions/2.7/lib/python2.7/site-packages/_pytest/core.py&amp;quot;, line 422, in __call__
    return self._docall(methods, kwargs)
  File &amp;quot;/Library/Frameworks/Python.framework/Versions/2.7/lib/python2.7/site-packages/_pytest/core.py&amp;quot;, line 433, in _docall
    res = mc.execute()
  File &amp;quot;/Library/Frameworks/Python.framework/Versions/2.7/lib/python2.7/site-packages/_pytest/core.py&amp;quot;, line 351, in execute
    res = method(**kwargs)
  File &amp;quot;/Library/Frameworks/Python.framework/Versions/2.7/lib/python2.7/site-packages/_pytest/runner.py&amp;quot;, line 62, in pytest_runtest_protocol
    runtestprotocol(item, nextitem=nextitem)
  File &amp;quot;/Library/Frameworks/Python.framework/Versions/2.7/lib/python2.7/site-packages/_pytest/runner.py&amp;quot;, line 69, in runtestprotocol
    reports.append(call_and_report(item, &amp;quot;call&amp;quot;, log))
  File &amp;quot;/Library/Frameworks/Python.framework/Versions/2.7/lib/python2.7/site-packages/_pytest/runner.py&amp;quot;, line 100, in call_and_report
    report = hook.pytest_runtest_makereport(item=item, call=call)
  File &amp;quot;/Library/Frameworks/Python.framework/Versions/2.7/lib/python2.7/site-packages/_pytest/main.py&amp;quot;, line 157, in call_matching_hooks
    return hookmethod.pcall(plugins, **kwargs)
  File &amp;quot;/Library/Frameworks/Python.framework/Versions/2.7/lib/python2.7/site-packages/_pytest/core.py&amp;quot;, line 426, in pcall
    return self._docall(methods, kwargs)
  File &amp;quot;/Library/Frameworks/Python.framework/Versions/2.7/lib/python2.7/site-packages/_pytest/core.py&amp;quot;, line 433, in _docall
    res = mc.execute()
  File &amp;quot;/Library/Frameworks/Python.framework/Versions/2.7/lib/python2.7/site-packages/_pytest/core.py&amp;quot;, line 351, in execute
    res = method(**kwargs)
  File &amp;quot;/Library/Frameworks/Python.framework/Versions/2.7/lib/python2.7/site-packages/_pytest/capture.py&amp;quot;, line 171, in pytest_runtest_makereport
    rep = __multicall__.execute()
  File &amp;quot;/Library/Frameworks/Python.framework/Versions/2.7/lib/python2.7/site-packages/_pytest/core.py&amp;quot;, line 351, in execute
    res = method(**kwargs)
  File &amp;quot;/Users/adam/work/saunter/py.saunter-examples/picpaste/webdriver/conftest.py&amp;quot;, line 47, in pytest_runtest_makereport
    s = saunter.saucelabs.SauceLabs(item, report)
TypeError: __init__() takes exactly 2 arguments (3 given)</error></testcase></testsuite>