<?xml version="1.0" encoding="utf-8"?><testsuite errors="0" failures="1" name="" skips="0" tests="1" time="25.068"><testcase classname="scripts.FileUpload.CheckFileUpload" name="test_local_upload" time="17.4519329071"><failure message="test failure">Traceback (most recent call last):
  File &quot;/Users/adam/work/saunter/py.saunter-examples/picpaste/webdriver/conftest.py&quot;, line 32, in pytest_runtest_call
    raise(e)
TimeoutException: Message: &apos;&apos;</failure></testcase></testsuite>